<!doctype html>
<html lang="en">
<head>
<meta charset="UTF-8">
<title>Error Handling</title>
</head>
<body>
Enter 1st number <input type="text" id="num1">
Enter 2nd number <input type="text" id="num2">
<button id="btn" onclick="sum()">Sum</button>
<p id="pid"></p>
</div>
</body>

<script>
// function sum(){
// let num1=document.getElementById("num1").value;
// let num2=document.getElementById("num2").value;
// let sumres=parseInt(num1)+parseInt(num2);
// document.getElementById("pid").innerHTML=sumres;
// console.log(sumres);
// //Error Handling
// setTimeout(()=>{
// try{
// console.log(UserError);
// }
// catch{
// console.log("The error created is catched");
// }
// },2000)

// setTimeout(
// ()=>{
// console.log("Sum complete");
// },3000
// );
// }


// try{
// errorCreated
// }
// catch(error){
// console.log(error.name);
// console.log(error.message);
// }


// try{
// let age=prompt("enter your age")
// age=Number.parseInt(age);
// if(age>100){
// throw new ReferenceError("Age is invalid");
// }
// }
// catch(error){
// console.log(error.name);
// console.log(error.message);
// }
// console.log("sript is still running");

let fun=()=>{
try{
console.log("we are in try");
console.log(a)//error created
}
catch(error){
console.log("The error is catched in catch block");
console.log(b);//new error created inside catch block
}
finally{
setTimeout(()=>{
console.log("This is in finally block and it will run without an error");
},2000)
}
}
fun();

</script>
</html>